Workbook

Sheet Fichier Anik et ajouts
A1: ID_JTL | B1: ID unique | C1: groupe_final | D1: pheno | E1: ech# Lipidomique | F1: ech Lipidomique | G1: ech AAAO | H1: age | I1: BMI | J1: sex | K1: NYHA | L1: Diabete | M1: gfr_CKDepi | N1: ST2 ng/mL | O1: Ct_FGF23_ELISARUmL | P1: NTproBNP | Q1: Tropo_T | R1: LA_Vol_simpsoni | S1: septalEeprim | T1: MeanVDOD | U1: LVEndoGLS | V1: LVMigm2 | W1: ECVpc | X1: dosageMyo1 | Y1: BPCO | Z1: SAS | AA1: Hb_gdL | AB1: loopdiuretics | AC1: CMI | AD1: FA_ATCD | AE1: EFsimpson | AF1: E_A | AG1: Mean_TAPSE | AH1: FUP 02/2019 résumé | AI1: DateBilan | AJ1: date FUP | AK1: Death | AL1: DateDeath_naturalhistory | AM1: TimeDeath_Nat_Hist_M | AN1: Hospit | AO1: DateHospit | AP1: TimeHospitM | AQ1: Combined | AR1: DateCombined | AS1: TimeCombinedM | AT1: Mean FUP months | AU1: MeanFUPdays | AV1: RVEndoGLSSib | AW1: Alanine | AX1: Arginine | AY1: Asparagine | AZ1: Aspartate | BA1: Cysteine | BB1: Glutamate | BC1: Glutamine | BD1: Glycine | BE1: Histidine | BF1: Hydroxyproline | BG1: Isoleucine | BH1: Leucine | BI1: Lysine | BJ1: Methionine | BK1: Phenylalanine | BL1: Proline | BM1: Serine | BN1: Threonine | BO1: Tryptophan | BP1: Tyrosine | BQ1: Valine | BR1: Acetoacetate | BS1: Alpha.hydroxy.butyrate | BT1: Alpha.keto.butyrate | BU1: Beta.hydroxy.butyrate | BV1: Citrate | BW1: Alpha.keto.glutarate | BX1: Lactate | BY1: Malate | BZ1: Pyruvate | CA1: Succinate | CB1: Lac_Pyr_ratio | CC1: BHB_AcAc_ratio | CD1: AHB_AKB_ratio
A2: 1 | B2: 1 | C2: 2 | D2: HFpEF | E2: 10429 | F2: YES | G2: YES | H2: 77 | I2: 27.34375 | J2: 1 | K2: 2 | L2: 0 | M2: 70 | N2: 44.46 | O2: 613.93854 | P2: 1519 | Q2: 11 | R2: 40.273951 | S2: 19.484848 | T2: 44 | U2: -19.67 | V2: 62.91479 | W2: 33.649027 | X2: 21.3037 | Y2: =VLOOKUP($A:$A,Variables_extraites!$A:$AD,7,FALSE) -> 0 | Z2: =VLOOKUP($A:$A,Variables_extraites!$A:$AD,8,FALSE) -> 1 | AA2: =VLOOKUP($A:$A,Variables_extraites!$A:$AD,9,FALSE) -> 12.2 | AB2: =VLOOKUP($A:$A,Variables_extraites!$A:$AD,10,FALSE) -> 1 | AC2: =VLOOKUP($A:$A,Variables_extraites!$A:$AD,11,FALSE) -> 0 | AD2: =VLOOKUP($A:$A,Variables_extraites!$A:$AD,12,FALSE) -> 1 | AE2: =VLOOKUP($A:$A,Variables_extraites!$A:$AD,13,FALSE) -> 62.124711 | AF2: =VLOOKUP($A:$A,Variables_extraites!$A:$AD,14,FALSE) -> NA | AG2: =VLOOKUP($A:$A,Variables_extraites!$A:$AD,15,FALSE) -> 14.333333 | AH2: =VLOOKUP($A:$A,Variables_extraites!$A:$AD,16,FALSE) -> 1 | AI2: =VLOOKUP($A:$A,Variables_extraites!$A:$AD,17,FALSE) -> 42065 | AJ2: =VLOOKUP($A:$A,Variables_extraites!$A:$AD,18,FALSE) -> 43514 | AK2: =VLOOKUP($A:$A,Variables_extraites!$A:$AD,19,FALSE) -> 0 | AL2: =VLOOKUP($A:$A,Variables_extraites!$A:$AD,20,FALSE) -> 43514 | AM2: =VLOOKUP($A:$A,Variables_extraites!$A:$AD,21,FALSE) -> 47 | AN2: =VLOOKUP($A:$A,Variables_extraites!$A:$AD,22,FALSE) -> 1 | AO2: =VLOOKUP($A:$A,Variables_extraites!$A:$AD,23,FALSE) -> 43166 | AP2: =VLOOKUP($A:$A,Variables_extraites!$A:$AD,24,FALSE) -> 36 | AQ2: =VLOOKUP($A:$A,Variables_extraites!$A:$AD,25,FALSE) -> 1 | AR2: =VLOOKUP($A:$A,Variables_extraites!$A:$AD,26,FALSE) -> 43166 | AS2: =VLOOKUP($A:$A,Variables_extraites!$A:$AD,27,FALSE) -> 36 | AT2: =VLOOKUP($A:$A,Variables_extraites!$A:$AD,28,FALSE) -> 47 | AU2: =VLOOKUP($A:$A,Variables_extraites!$A:$AD,29,FALSE) -> 1449 | AV2: =VLOOKUP($A:$A,Variables_extraites!$A:$AD,30,FALSE) -> NA | AW2: 8.1396025 | AX2: 7.2647241 | AY2: 5.0343038 | AZ2: 2.4541759 | BA2: 7.9648029 | BB2: 5.9692426 | BC2: 9.3438519 | BD2: 7.7308437 | BE2: 6.1045463 | BF2: 1.1375035 | BG2: 5.8389518 | BH2: 6.6516258 | BI2: 7.0936024 | BJ2: 4.4918531 | BK2: 5.9995491 | BL2: 7.7457751 | BM2: 6.2692202 | BN2: 6.8417216 | BO2: 5.78999 | BP2: 6.0338635 | BQ2: 7.8819093 | BR2: 3.7463128 | BS2: 10.419476 | BT2: 1.448901 | BU2: 5.549053 | BV2: 6.9525665 | BW2: 5.7931156 | BX2: 10.891974 | BY2: 3.6380738 | BZ2: 8.2183937 | CA2: 4.592756 | CB2: 2.6735798 | CC2: 1.8027403 | CD2: 8.9705747
A3: 2 | B3: 2 | C3: 2 | D3: HFpEF | E3: 10297 | F3: YES | H3: 75 | I3: 21.612812 | J3: 1 | K3: 4 | L3: 0 | M3: 84 | N3: 34.58 | O3: 173.36512 | P3: 1597 | Q3: 48 | R3: 60.892985 | S3: 16.4 | T3: 37 | U3: -16.9 | V3: 56.589862 | W3: 33.516899 | X3: 23.4603 | Y3: =VLOOKUP($A:$A,Variables_extraites!$A:$AD,7,FALSE) -> 0 | Z3: =VLOOKUP($A:$A,Variables_extraites!$A:$AD,8,FALSE) -> 0 | AA3: =VLOOKUP($A:$A,Variables_extraites!$A:$AD,9,FALSE) -> 9.8 | AB3: =VLOOKUP($A:$A,Variables_extraites!$A:$AD,10,FALSE) -> 1 | AC3: =VLOOKUP($A:$A,Variables_extraites!$A:$AD,11,FALSE) -> 0 | AD3: =VLOOKUP($A:$A,Variables_extraites!$A:$AD,12,FALSE) -> 1 | AE3: =VLOOKUP($A:$A,Variables_extraites!$A:$AD,13,FALSE) -> 54.750594 | AF3: =VLOOKUP($A:$A,Variables_extraites!$A:$AD,14,FALSE) -> 1 | AG3: =VLOOKUP($A:$A,Variables_extraites!$A:$AD,15,FALSE) -> 30 | AH3: =VLOOKUP($A:$A,Variables_extraites!$A:$AD,16,FALSE) -> 2 | AI3: =VLOOKUP($A:$A,Variables_extraites!$A:$AD,17,FALSE) -> 42317 | AJ3: =VLOOKUP($A:$A,Variables_extraites!$A:$AD,18,FALSE) -> 43272 | AK3: =VLOOKUP($A:$A,Variables_extraites!$A:$AD,19,FALSE) -> 0 | AL3: =VLOOKUP($A:$A,Variables_extraites!$A:$AD,20,FALSE) -> 43272 | AM3: =VLOOKUP($A:$A,Variables_extraites!$A:$AD,21,FALSE) -> 31 | AN3: =VLOOKUP($A:$A,Variables_extraites!$A:$AD,22,FALSE) -> 0 | AO3: =VLOOKUP($A:$A,Variables_extraites!$A:$AD,23,FALSE) -> 43272 | AP3: =VLOOKUP($A:$A,Variables_extraites!$A:$AD,24,FALSE) -> 31 | AQ3: =VLOOKUP($A:$A,Variables_extraites!$A:$AD,25,FALSE) -> 0 | AR3: =VLOOKUP($A:$A,Variables_extraites!$A:$AD,26,FALSE) -> 43272 | AS3: =VLOOKUP($A:$A,Variables_extraites!$A:$AD,27,FALSE) -> 31 | AT3: =VLOOKUP($A:$A,Variables_extraites!$A:$AD,28,FALSE) -> 31 | AU3: =VLOOKUP($A:$A,Variables_extraites!$A:$AD,29,FALSE) -> 955 | AV3: =VLOOKUP($A:$A,Variables_extraites!$A:$AD,30,FALSE) -> -22.89
A4: 5 | B4: 5 | C4: 2 | D4: HFpEF | E4: 10547 | F4: YES | G4: YES | H4: 67 | I4: 30.42185 | J4: 0 | K4: 0 | L4: 1 | M4: 79 | N4: 24.48 | O4: 49.122977 | P4: 483.8 | Q4: 14 | R4: 45.350504 | S4: 18.928571 | T4: 34 | U4: -20.12 | V4: 65.941287 | W4: 33.789973 | X4: 25.5106 | Y4: =VLOOKUP($A:$A,Variables_extraites!$A:$AD,7,FALSE) -> 0 | Z4: =VLOOKUP($A:$A,Variables_extraites!$A:$AD,8,FALSE) -> 0 | AA4: =VLOOKUP($A:$A,Variables_extraites!$A:$AD,9,FALSE) -> 11.1 | AB4: =VLOOKUP($A:$A,Variables_extraites!$A:$AD,10,FALSE) -> 0 | AC4: =VLOOKUP($A:$A,Variables_extraites!$A:$AD,11,FALSE) -> 1 | AD4: =VLOOKUP($A:$A,Variables_extraites!$A:$AD,12,FALSE) -> 1 | AE4: =VLOOKUP($A:$A,Variables_extraites!$A:$AD,13,FALSE) -> 65.268139 | AF4: =VLOOKUP($A:$A,Variables_extraites!$A:$AD,14,FALSE) -> 1.8275862 | AG4: =VLOOKUP($A:$A,Variables_extraites!$A:$AD,15,FALSE) -> 15 | AH4: =VLOOKUP($A:$A,Variables_extraites!$A:$AD,16,FALSE) -> 5 | AI4: =VLOOKUP($A:$A,Variables_extraites!$A:$AD,17,FALSE) -> 42262 | AJ4: =VLOOKUP($A:$A,Variables_extraites!$A:$AD,18,FALSE) -> 43048 | AK4: =VLOOKUP($A:$A,Variables_extraites!$A:$AD,19,FALSE) -> 0 | AL4: =VLOOKUP($A:$A,Variables_extraites!$A:$AD,20,FALSE) -> 43048 | AM4: =VLOOKUP($A:$A,Variables_extraites!$A:$AD,21,FALSE) -> 26 | AN4: =VLOOKUP($A:$A,Variables_extraites!$A:$AD,22,FALSE) -> 0 | AO4: =VLOOKUP($A:$A,Variables_extraites!$A:$AD,23,FALSE) -> 43048 | AP4: =VLOOKUP($A:$A,Variables_extraites!$A:$AD,24,FALSE) -> 26 | AQ4: =VLOOKUP($A:$A,Variables_extraites!$A:$AD,25,FALSE) -> 0 | AR4: =VLOOKUP($A:$A,Variables_extraites!$A:$AD,26,FALSE) -> 43048 | AS4: =VLOOKUP($A:$A,Variables_extraites!$A:$AD,27,FALSE) -> 26 | AT4: =VLOOKUP($A:$A,Variables_extraites!$A:$AD,28,FALSE) -> 25.8 | AU4: =VLOOKUP($A:$A,Variables_extraites!$A:$AD,29,FALSE) -> 786 | AV4: =VLOOKUP($A:$A,Variables_extraites!$A:$AD,30,FALSE) -> -20.5 | AW4: 9.0643116 | AX4: 7.5465858 | AY4: 5.4299507 | AZ4: 2.1731274 | BA4: 7.8492487 | BB4: 6.274448 | BC4: 9.3467353 | BD4: 8.0001691 | BE4: 5.895545 | BF4: 1.0840643 | BG4: 5.9970665 | BH4: 5.9136075 | BI4: 7.1428218 | BJ4: 4.3059705 | BK4: 5.6070343 | BL4: 7.9457364 | BM4: 6.6088092 | BN4: 6.4899282 | BO4: 5.2816983 | BP4: 5.4763817 | BQ4: 7.0214797 | BR4: 0.29865832 | BS4: 9.620843 | BT4: 1.3729521 | BU4: 5.6513388 | BV4: 7.21072 | BW4: 5.7106687 | BX4: 12.096 | BY4: 3.7322692 | BZ4: 9.548976 | CA4: 3.9532652 | CB4: 2.5470242 | CC4: 5.3526805 | CD4: 8.2478909
A5: 6 | B5: 6 | C5: 2 | D5: HFpEF | E5: 10552 | F5: YES | H5: 77 | I5: 25.925926 | J5: 0 | K5: 4 | L5: 0 | M5: 48 | N5: 57.88 | O5: 122.11922 | R5: 44.793314 | S5: 14.341463 | T5: 40 | U5: -18.81 | V5: 64.171086 | W5: 32.847686 | X5: 39.9844 | Y5: =VLOOKUP($A:$A,Variables_extraites!$A:$AD,7,FALSE) -> 1 | Z5: =VLOOKUP($A:$A,Variables_extraites!$A:$AD,8,FALSE) -> 0 | AA5: =VLOOKUP($A:$A,Variables_extraites!$A:$AD,9,FALSE) -> 16.7 | AB5: =VLOOKUP($A:$A,Variables_extraites!$A:$AD,10,FALSE) -> 0 | AC5: =VLOOKUP($A:$A,Variables_extraites!$A:$AD,11,FALSE) -> 0 | AD5: =VLOOKUP($A:$A,Variables_extraites!$A:$AD,12,FALSE) -> 1 | AE5: =VLOOKUP($A:$A,Variables_extraites!$A:$AD,13,FALSE) -> 67.320261 | AF5: =VLOOKUP($A:$A,Variables_extraites!$A:$AD,14,FALSE) -> NA | AG5: =VLOOKUP($A:$A,Variables_extraites!$A:$AD,15,FALSE) -> 15 | AH5: =VLOOKUP($A:$A,Variables_extraites!$A:$AD,16,FALSE) -> 6 | AI5: =VLOOKUP($A:$A,Variables_extraites!$A:$AD,17,FALSE) -> 42156 | AJ5: =VLOOKUP($A:$A,Variables_extraites!$A:$AD,18,FALSE) -> 43048 | AK5: =VLOOKUP($A:$A,Variables_extraites!$A:$AD,19,FALSE) -> 0 | AL5: =VLOOKUP($A:$A,Variables_extraites!$A:$AD,20,FALSE) -> 43048 | AM5: =VLOOKUP($A:$A,Variables_extraites!$A:$AD,21,FALSE) -> 29 | AN5: =VLOOKUP($A:$A,Variables_extraites!$A:$AD,22,FALSE) -> 1 | AO5: =VLOOKUP($A:$A,Variables_extraites!$A:$AD,23,FALSE) -> 42401 | AP5: =VLOOKUP($A:$A,Variables_extraites!$A:$AD,24,FALSE) -> 8 | AQ5: =VLOOKUP($A:$A,Variables_extraites!$A:$AD,25,FALSE) -> 1 | AR5: =VLOOKUP($A:$A,Variables_extraites!$A:$AD,26,FALSE) -> 42401 | AS5: =VLOOKUP($A:$A,Variables_extraites!$A:$AD,27,FALSE) -> 8 | AT5: =VLOOKUP($A:$A,Variables_extraites!$A:$AD,28,FALSE) -> 29.33 | AU5: =VLOOKUP($A:$A,Variables_extraites!$A:$AD,29,FALSE) -> 892 | AV5: =VLOOKUP($A:$A,Variables_extraites!$A:$AD,30,FALSE) -> -21.37
A6: 8 | B6: 8 | C6: 2 | D6: HFpEF | E6: 10477 | F6: YES | H6: 78 | I6: 34.722222 | J6: 0 | K6: 2 | L6: 1 | M6: 62 | N6: 55.55 | O6: 545.5079 | P6: 3605 | Q6: 17 | R6: 46.809838 | S6: 20.87619 | T6: 38.6 | U6: -14.33 | V6: 82.605597 | W6: 36.531472 | X6: 24.39 | Y6: =VLOOKUP($A:$A,Variables_extraites!$A:$AD,7,FALSE) -> 0 | Z6: =VLOOKUP($A:$A,Variables_extraites!$A:$AD,8,FALSE) -> 1 | AA6: =VLOOKUP($A:$A,Variables_extraites!$A:$AD,9,FALSE) -> 13.8 | AB6: =VLOOKUP($A:$A,Variables_extraites!$A:$AD,10,FALSE) -> 1 | AC6: =VLOOKUP($A:$A,Variables_extraites!$A:$AD,11,FALSE) -> 1 | AD6: =VLOOKUP($A:$A,Variables_extraites!$A:$AD,12,FALSE) -> 1 | AE6: =VLOOKUP($A:$A,Variables_extraites!$A:$AD,13,FALSE) -> 52.132289 | AF6: =VLOOKUP($A:$A,Variables_extraites!$A:$AD,14,FALSE) -> NA | AG6: =VLOOKUP($A:$A,Variables_extraites!$A:$AD,15,FALSE) -> 12.5 | AH6: =VLOOKUP($A:$A,Variables_extraites!$A:$AD,16,FALSE) -> 8 | AI6: =VLOOKUP($A:$A,Variables_extraites!$A:$AD,17,FALSE) -> 42129 | AJ6: =VLOOKUP($A:$A,Variables_extraites!$A:$AD,18,FALSE) -> 43040 | AK6: =VLOOKUP($A:$A,Variables_extraites!$A:$AD,19,FALSE) -> 1 | AL6: =VLOOKUP($A:$A,Variables_extraites!$A:$AD,20,FALSE) -> 43040 | AM6: =VLOOKUP($A:$A,Variables_extraites!$A:$AD,21,FALSE) -> 29 | AN6: =VLOOKUP($A:$A,Variables_extraites!$A:$AD,22,FALSE) -> 1 | AO6: =VLOOKUP($A:$A,Variables_extraites!$A:$AD,23,FALSE) -> 42152 | AP6: =VLOOKUP($A:$A,Variables_extraites!$A:$AD,24,FALSE) -> 1 | AQ6: =VLOOKUP($A:$A,Variables_extraites!$A:$AD,25,FALSE) -> 1 | AR6: =VLOOKUP($A:$A,Variables_extraites!$A:$AD,26,FALSE) -> 42152 | AS6: =VLOOKUP($A:$A,Variables_extraites!$A:$AD,27,FALSE) -> 1 | AT6: =VLOOKUP($A:$A,Variables_extraites!$A:$AD,28,FALSE) -> 29 | AU6: =VLOOKUP($A:$A,Variables_extraites!$A:$AD,29,FALSE) -> 911 | AV6: =VLOOKUP($A:$A,Variables_extraites!$A:$AD,30,FALSE) -> NA
A7: 9 | B7: 9 | C7: 2 | D7: HFpEF | E7: 10298 | F7: YES | G7: YES | H7: 84 | I7: 24.221453 | J7: 1 | K7: 3 | L7: 1 | M7: 20 | N7: 85.09 | O7: 1335.7059 | P7: 6563 | Q7: 77 | R7: 72.663664 | S7: 28.888889 | T7: 43 | U7: -17.17 | X7: 75.9158 | Y7: =VLOOKUP($A:$A,Variables_extraites!$A:$AD,7,FALSE) -> 0 | Z7: =VLOOKUP($A:$A,Variables_extraites!$A:$AD,8,FALSE) -> 0 | AA7: =VLOOKUP($A:$A,Variables_extraites!$A:$AD,9,FALSE) -> 9 | AB7: =VLOOKUP($A:$A,Variables_extraites!$A:$AD,10,FALSE) -> 1 | AC7: =VLOOKUP($A:$A,Variables_extraites!$A:$AD,11,FALSE) -> 1 | AD7: =VLOOKUP($A:$A,Variables_extraites!$A:$AD,12,FALSE) -> 0 | AE7: =VLOOKUP($A:$A,Variables_extraites!$A:$AD,13,FALSE) -> 60.399285 | AF7: =VLOOKUP($A:$A,Variables_extraites!$A:$AD,14,FALSE) -> 1.0586319 | AG7: =VLOOKUP($A:$A,Variables_extraites!$A:$AD,15,FALSE) -> 16 | AH7: =VLOOKUP($A:$A,Variables_extraites!$A:$AD,16,FALSE) -> 9 | AI7: =VLOOKUP($A:$A,Variables_extraites!$A:$AD,17,FALSE) -> 42345 | AJ7: =VLOOKUP($A:$A,Variables_extraites!$A:$AD,18,FALSE) -> 42622 | AK7: =VLOOKUP($A:$A,Variables_extraites!$A:$AD,19,FALSE) -> 1 | AL7: =VLOOKUP($A:$A,Variables_extraites!$A:$AD,20,FALSE) -> 42622 | AM7: =VLOOKUP($A:$A,Variables_extraites!$A:$AD,21,FALSE) -> 9 | AN7: =VLOOKUP($A:$A,Variables_extraites!$A:$AD,22,FALSE) -> 1 | AO7: =VLOOKUP($A:$A,Variables_extraites!$A:$AD,23,FALSE) -> 42397 | AP7: =VLOOKUP($A:$A,Variables_extraites!$A:$AD,24,FALSE) -> 2 | AQ7: =VLOOKUP($A:$A,Variables_extraites!$A:$AD,25,FALSE) -> 1 | AR7: =VLOOKUP($A:$A,Variables_extraites!$A:$AD,26,FALSE) -> 42397 | AS7: =VLOOKUP($A:$A,Variables_extraites!$A:$AD,27,FALSE) -> 2 | AT7: =VLOOKUP($A:$A,Variables_extraites!$A:$AD,28,FALSE) -> 9 | AU7: =VLOOKUP($A:$A,Variables_extraites!$A:$AD,29,FALSE) -> 277 | AV7: =VLOOKUP($A:$A,Variables_extraites!$A:$AD,30,FALSE) -> -20.25 | AW7: 7.6067383 | AX7: 7.397974 | AY7: 5.0461418 | AZ7: 3.1243281 | BA7: 8.5007622 | BB7: 7.1183182 | BC7: 9.1011353 | BD7: 7.9936178 | BE7: 6.3774708 | BF7: 1.1570437 | BG7: 5.6965503 | BH7: 6.3492591 | BI7: 7.5947725 | BJ7: 4.5310695 | BK7: 5.9579146 | BL7: 7.8323837 | BM7: 6.2641611 | BN7: 7.5291963 | BO7: 4.6322682 | BP7: 5.9300276 | BQ7: 7.4654031 | BR7: 0.33342373 | BS7: 10.692816 | BT7: 1.1309309 | BU7: 8.7794567 | BV7: 6.7059779 | BW7: 5.7438919 | BX7: 11.253038 | BY7: 3.5789387 | BZ7: 7.7380923 | CA7: 4.3096128 | CB7: 3.5149456 | CC7: 8.446033 | CD7: 9.5618851
A8: 10 | B8: 10 | C8: 2 | D8: HFpEF | E8: 10332 | F8: YES | G8: YES | H8: 81 | I8: 31.64557 | J8: 1 | K8: 3 | L8: 0 | M8: 48 | N8: 21.97 | O8: 150.29696 | P8: 1717 | Q8: 17 | S8: 17.610063 | T8: 36 | U8: -19.123333 | V8: 40.958825 | W8: 29.127333 | X8: 60.3901 | Y8: =VLOOKUP($A:$A,Variables_extraites!$A:$AD,7,FALSE) -> 0 | Z8: =VLOOKUP($A:$A,Variables_extraites!$A:$AD,8,FALSE) -> 0 | AA8: =VLOOKUP($A:$A,Variables_extraites!$A:$AD,9,FALSE) -> 11.3 | AB8: =VLOOKUP($A:$A,Variables_extraites!$A:$AD,10,FALSE) -> 1 | AC8: =VLOOKUP($A:$A,Variables_extraites!$A:$AD,11,FALSE) -> 0 | AD8: =VLOOKUP($A:$A,Variables_extraites!$A:$AD,12,FALSE) -> 1 | AE8: =VLOOKUP($A:$A,Variables_extraites!$A:$AD,13,FALSE) -> 66.397985 | AF8: =VLOOKUP($A:$A,Variables_extraites!$A:$AD,14,FALSE) -> NA | AG8: =VLOOKUP($A:$A,Variables_extraites!$A:$AD,15,FALSE) -> 23 | AH8: =VLOOKUP($A:$A,Variables_extraites!$A:$AD,16,FALSE) -> 10 | AI8: =VLOOKUP($A:$A,Variables_extraites!$A:$AD,17,FALSE) -> 42041 | AJ8: =VLOOKUP($A:$A,Variables_extraites!$A:$AD,18,FALSE) -> 43480 | AK8: =VLOOKUP($A:$A,Variables_extraites!$A:$AD,19,FALSE) -> 0 | AL8: =VLOOKUP($A:$A,Variables_extraites!$A:$AD,20,FALSE) -> 43480 | AM8: =VLOOKUP($A:$A,Variables_extraites!$A:$AD,21,FALSE) -> 47 | AN8: =VLOOKUP($A:$A,Variables_extraites!$A:$AD,22,FALSE) -> 1 | AO8: =VLOOKUP($A:$A,Variables_extraites!$A:$AD,23,FALSE) -> 42873 | AP8: =VLOOKUP($A:$A,Variables_extraites!$A:$AD,24,FALSE) -> 27 | AQ8: =VLOOKUP($A:$A,Variables_extraites!$A:$AD,25,FALSE) -> 1 | AR8: =VLOOKUP($A:$A,Variables_extraites!$A:$AD,26,FALSE) -> 42873 | AS8: =VLOOKUP($A:$A,Variables_extraites!$A:$AD,27,FALSE) -> 27 | AT8: =VLOOKUP($A:$A,Variables_extraites!$A:$AD,28,FALSE) -> 47 | AU8: =VLOOKUP($A:$A,Variables_extraites!$A:$AD,29,FALSE) -> 1439 | AV8: =VLOOKUP($A:$A,Variables_extraites!$A:$AD,30,FALSE) -> -25.97 | AW8: 8.7643408 | AX8: 8.0100525 | AY8: 5.1034976 | AZ8: 2.5360529 | BA8: 8.0101085 | BB8: 5.5625477 | BC8: 9.4409107 | BD8: 8.0997686 | BE8: 6.2479275 | BF8: 1.5410192 | BG8: 5.8945753 | BH8: 6.1963316 | BI8: 7.611615 | BJ8: 4.3154213 | BK8: 5.8797058 | BL8: 8.0465784 | BM8: 6.4955353 | BN8: 6.6697355 | BO8: 5.3034155 | BP8: 5.7202785 | BQ8: 7.2983834 | BR8: 2.8399596 | BS8: 9.7109442 | BT8: 1.6599246 | BU8: 6.1616862 | BV8: 7.0660892 | BW8: 5.5369854 | BX8: 10.160262 | BY8: 3.3434078 | BZ8: 7.8101217 | CA8: 4.4032677 | CB8: 2.3501405 | CC8: 3.3217266 | CD8: 8.0510196
A9: 12 | B9: 12 | C9: 2 | D9: HFpEF | E9: 10363 | F9: YES | G9: YES | H9: 83 | I9: 29.937595 | J9: 1 | K9: 2 | L9: 1 | M9: 94 | N9: 55.8 | O9: 204.47624 | R9: 47.411341 | S9: 23.243243 | T9: 58.5 | U9: -14.7 | V9: 55.576294 | W9: 31.531215 | X9: 38.5647 | Y9: =VLOOKUP($A:$A,Variables_extraites!$A:$AD,7,FALSE) -> 0 | Z9: =VLOOKUP($A:$A,Variables_extraites!$A:$AD,8,FALSE) -> 0 | AA9: =VLOOKUP($A:$A,Variables_extraites!$A:$AD,9,FALSE) -> 13.4 | AB9: =VLOOKUP($A:$A,Variables_extraites!$A:$AD,10,FALSE) -> 1 | AC9: =VLOOKUP($A:$A,Variables_extraites!$A:$AD,11,FALSE) -> 1 | AD9: =VLOOKUP($A:$A,Variables_extraites!$A:$AD,12,FALSE) -> 0 | AE9: =VLOOKUP($A:$A,Variables_extraites!$A:$AD,13,FALSE) -> 81.558935 | AF9: =VLOOKUP($A:$A,Variables_extraites!$A:$AD,14,FALSE) -> 2.047619 | AG9: =VLOOKUP($A:$A,Variables_extraites!$A:$AD,15,FALSE) -> 16 | AH9: =VLOOKUP($A:$A,Variables_extraites!$A:$AD,16,FALSE) -> 12 | AI9: =VLOOKUP($A:$A,Variables_extraites!$A:$AD,17,FALSE) -> 42254 | AJ9: =VLOOKUP($A:$A,Variables_extraites!$A:$AD,18,FALSE) -> 43119 | AK9: =VLOOKUP($A:$A,Variables_extraites!$A:$AD,19,FALSE) -> 0 | AL9: =VLOOKUP($A:$A,Variables_extraites!$A:$AD,20,FALSE) -> 43119 | AM9: =VLOOKUP($A:$A,Variables_extraites!$A:$AD,21,FALSE) -> 28 | AN9: =VLOOKUP($A:$A,Variables_extraites!$A:$AD,22,FALSE) -> 1 | AO9: =VLOOKUP($A:$A,Variables_extraites!$A:$AD,23,FALSE) -> 43119 | AP9: =VLOOKUP($A:$A,Variables_extraites!$A:$AD,24,FALSE) -> 28 | AQ9: =VLOOKUP($A:$A,Variables_extraites!$A:$AD,25,FALSE) -> 1 | AR9: =VLOOKUP($A:$A,Variables_extraites!$A:$AD,26,FALSE) -> 43119 | AS9: =VLOOKUP($A:$A,Variables_extraites!$A:$AD,27,FALSE) -> 28 | AT9: =VLOOKUP($A:$A,Variables_extraites!$A:$AD,28,FALSE) -> 28 | AU9: =VLOOKUP($A:$A,Variables_extraites!$A:$AD,29,FALSE) -> 865 | AV9: =VLOOKUP($A:$A,Variables_extraites!$A:$AD,30,FALSE) -> -17.56 | AW9: 8.7237292 | AX9: 7.4976124 | AY9: 5.1830895 | AZ9: 3.7824086 | BA9: 7.6510517 | BB9: 8.6892642 | BC9: 7.8963324 | BD9: 8.0714624 | BE9: 6.2176185 | BF9: 1.1375035 | BG9: 5.8482474 | BH9: 6.5161728 | BI9: 7.7338966 | BJ9: 4.7980505 | BK9: 5.9646297 | BL9: 7.8261035 | BM9: 6.7068068 | BN9: 7.219459 | BO9: 6.1731274 | BP9: 6.2772409 | BQ9: 7.5970097 | BR9: -0.32192809 | BS9: 10.3928 | BT9: 0.23878686 | BU9: 5.5888645 | BV9: 6.6444332 | BW9: 5.4469179 | BX9: 11.140203 | BY9: 3.4711875 | BZ9: 6.5722834 | CA9: 4.6135317 | CB9: 4.5679201 | CC9: 5.9107926 | CD9: 10.154014
A10: 16 | B10: 16 | C10: 2 | D10: HFpEF | E10: 10550 | F10: YES | G10: YES | H10: 79 | I10: 32.653061 | J10: 0 | K10: 2 | L10: 0 | M10: 97 | N10: 41.25 | O10: 92.974799 | P10: 1029 | Q10: 17 | R10: 62.283615 | S10: 22.222222 | T10: 41 | U10: -13.1 | X10: 36.6252 | Y10: =VLOOKUP($A:$A,Variables_extraites!$A:$AD,7,FALSE) -> 0 | Z10: =VLOOKUP($A:$A,Variables_extraites!$A:$AD,8,FALSE) -> 1 | AA10: =VLOOKUP($A:$A,Variables_extraites!$A:$AD,9,FALSE) -> 14.5 | AB10: =VLOOKUP($A:$A,Variables_extraites!$A:$AD,10,FALSE) -> 1 | AC10: =VLOOKUP($A:$A,Variables_extraites!$A:$AD,11,FALSE) -> 0 | AD10: =VLOOKUP($A:$A,Variables_extraites!$A:$AD,12,FALSE) -> 1 | AE10: =VLOOKUP($A:$A,Variables_extraites!$A:$AD,13,FALSE) -> 60.529831 | AF10: =VLOOKUP($A:$A,Variables_extraites!$A:$AD,14,FALSE) -> NA | AG10: =VLOOKUP($A:$A,Variables_extraites!$A:$AD,15,FALSE) -> 19 | AH10: =VLOOKUP($A:$A,Variables_extraites!$A:$AD,16,FALSE) -> 16 | AI10: =VLOOKUP($A:$A,Variables_extraites!$A:$AD,17,FALSE) -> 42345 | AJ10: =VLOOKUP($A:$A,Variables_extraites!$A:$AD,18,FALSE) -> 43398 | AK10: =VLOOKUP($A:$A,Variables_extraites!$A:$AD,19,FALSE) -> 0 | AL10: =VLOOKUP($A:$A,Variables_extraites!$A:$AD,20,FALSE) -> 43398 | AM10: =VLOOKUP($A:$A,Variables_extraites!$A:$AD,21,FALSE) -> 34 | AN10: =VLOOKUP($A:$A,Variables_extraites!$A:$AD,22,FALSE) -> 1 | AO10: =VLOOKUP($A:$A,Variables_extraites!$A:$AD,23,FALSE) -> 42522 | AP10: =VLOOKUP($A:$A,Variables_extraites!$A:$AD,24,FALSE) -> 5 | AQ10: =VLOOKUP($A:$A,Variables_extraites!$A:$AD,25,FALSE) -> 1 | AR10: =VLOOKUP($A:$A,Variables_extraites!$A:$AD,26,FALSE) -> 42522 | AS10: =VLOOKUP($A:$A,Variables_extraites!$A:$AD,27,FALSE) -> 5 | AT10: =VLOOKUP($A:$A,Variables_extraites!$A:$AD,28,FALSE) -> 34 | AU10: =VLOOKUP($A:$A,Variables_extraites!$A:$AD,29,FALSE) -> 1053 | AV10: =VLOOKUP($A:$A,Variables_extraites!$A:$AD,30,FALSE) -> -15.01 | AW10: 8.3718637 | AX10: 7.184677 | AY10: 4.9832217 | AZ10: 1.5509007 | BA10: 7.9629538 | BB10: 5.6182387 | BC10: 9.2555715 | BD10: 7.739173 | BE10: 6.0995056 | BF10: 1.1043367 | BG10: 5.4809113 | BH10: 5.9257621 | BI10: 7.182593 | BJ10: 4.0992952 | BK10: 5.7628803 | BL10: 7.6037747 | BM10: 6.4836546 | BN10: 6.5349642 | BO10: 5.6276068 | BP10: 5.4947356 | BQ10: 7.5376843 | BR10: 1.3103401 | BS10: 9.7673237 | BT10: 1.9855004 | BU10: 3.6403896 | BV10: 7.0748907 | BW10: 4.8904467 | BX10: 10.618936 | BY10: 3.1309309 | BZ10: 8.6093635 | CA10: 3.945795 | CB10: 2.0095726 | CC10: 2.3300494 | CD10: 7.7818233
A11: 17 | B11: 17 | C11: 2 | D11: HFpEF | E11: 10430 | F11: YES | G11: YES | H11: 84 | I11: 37.465565 | J11: 1 | K11: 2 | L11: 0 | M11: 35 | N11: 55.44 | O11: 243.67733 | P11: 4680 | Q11: 31 | R11: 33.874696 | S11: 34.333333 | T11: 22 | U11: -22.5 | V11: 65.825572 | W11: 33.348859 | X11: 159.4128 | Y11: =VLOOKUP($A:$A,Variables_extraites!$A:$AD,7,FALSE) -> 0 | Z11: =VLOOKUP($A:$A,Variables_extraites!$A:$AD,8,FALSE) -> 0 | AA11: =VLOOKUP($A:$A,Variables_extraites!$A:$AD,9,FALSE) -> 9.7 | AB11: =VLOOKUP($A:$A,Variables_extraites!$A:$AD,10,FALSE) -> 1 | AC11: =VLOOKUP($A:$A,Variables_extraites!$A:$AD,11,FALSE) -> 1 | AD11: =VLOOKUP($A:$A,Variables_extraites!$A:$AD,12,FALSE) -> 0 | AE11: =VLOOKUP($A:$A,Variables_extraites!$A:$AD,13,FALSE) -> 76.108871 | AF11: =VLOOKUP($A:$A,Variables_extraites!$A:$AD,14,FALSE) -> 0.93570929 | AG11: =VLOOKUP($A:$A,Variables_extraites!$A:$AD,15,FALSE) -> 19 | AH11: =VLOOKUP($A:$A,Variables_extraites!$A:$AD,16,FALSE) -> 17 | AI11: =VLOOKUP($A:$A,Variables_extraites!$A:$AD,17,FALSE) -> 42255 | AJ11: =VLOOKUP($A:$A,Variables_extraites!$A:$AD,18,FALSE) -> 43229 | AK11: =VLOOKUP($A:$A,Variables_extraites!$A:$AD,19,FALSE) -> 0 | AL11: =VLOOKUP($A:$A,Variables_extraites!$A:$AD,20,FALSE) -> 43229 | AM11: =VLOOKUP($A:$A,Variables_extraites!$A:$AD,21,FALSE) -> 32 | AN11: =VLOOKUP($A:$A,Variables_extraites!$A:$AD,22,FALSE) -> 0 | AO11: =VLOOKUP($A:$A,Variables_extraites!$A:$AD,23,FALSE) -> 43229 | AP11: =VLOOKUP($A:$A,Variables_extraites!$A:$AD,24,FALSE) -> 32 | AQ11: =VLOOKUP($A:$A,Variables_extraites!$A:$AD,25,FALSE) -> 0 | AR11: =VLOOKUP($A:$A,Variables_extraites!$A:$AD,26,FALSE) -> 43229 | AS11: =VLOOKUP($A:$A,Variables_extraites!$A:$AD,27,FALSE) -> 32 | AT11: =VLOOKUP($A:$A,Variables_extraites!$A:$AD,28,FALSE) -> 32 | AU11: =VLOOKUP($A:$A,Variables_extraites!$A:$AD,29,FALSE) -> 974 | AV11: =VLOOKUP($A:$A,Variables_extraites!$A:$AD,30,FALSE) -> -33.47 | AW11: 8.2158727 | AX11: 7.654278 | AY11: 4.6455864 | AZ11: 2.6712934 | BA11: 7.3810237 | BB11: 8.0227007 | BC11: 7.9070709 | BD11: 7.6486092 | BE11: 5.949068 | BF11: 1.3895668 | BG11: 6.2387869 | BH11: 6.7110819 | BI11: 7.5835341 | BJ11: 4.33985 | BK11: 6.0024775 | BL11: 7.7533505 | BM11: 6.3824943 | BN11: 6.2605903 | BO11: 5.9724629 | BP11: 5.6670406 | BQ11: 7.7528155 | BR11: -1.9378783 | BS11: 11.024606 | BT11: 1.6276068 | BU11: 6.9776234 | BV11: 6.9419279 | BW11: 5.3273281 | BX11: 10.639006 | BY11: 3.1890338 | BZ11: 7.0571253 | CA11: 4.3412742 | CB11: 3.5818807 | CC11: 8.9155017 | CD11: 9.3969996
A12: 21 | B12: 21 | C12: 2 | D12: HFpEF | E12: 10364 | F12: YES | H12: 71 | I12: 39.519741 | J12: 1 | K12: 2 | L12: 1 | M12: 50 | N12: 35.45 | O12: 308.78077 | P12: 613.8 | Q12: 13 | R12: 36.490252 | S12: 12 | T12: 26 | U12: -17.5 | V12: 64.819747 | W12: 30.408878 | X12: 98.7428 | Y12: =VLOOKUP($A:$A,Variables_extraites!$A:$AD,7,FALSE) -> 0 | Z12: =VLOOKUP($A:$A,Variables_extraites!$A:$AD,8,FALSE) -> 1 | AA12: =VLOOKUP($A:$A,Variables_extraites!$A:$AD,9,FALSE) -> 11.1 | AB12: =VLOOKUP($A:$A,Variables_extraites!$A:$AD,10,FALSE) -> 0 | AC12: =VLOOKUP($A:$A,Variables_extraites!$A:$AD,11,FALSE) -> 1 | AD12: =VLOOKUP($A:$A,Variables_extraites!$A:$AD,12,FALSE) -> 1 | AE12: =VLOOKUP($A:$A,Variables_extraites!$A:$AD,13,FALSE) -> 63.500305 | AF12: =VLOOKUP($A:$A,Variables_extraites!$A:$AD,14,FALSE) -> 0.76190476 | AG12: =VLOOKUP($A:$A,Variables_extraites!$A:$AD,15,FALSE) -> 27 | AH12: =VLOOKUP($A:$A,Variables_extraites!$A:$AD,16,FALSE) -> 21 | AI12: =VLOOKUP($A:$A,Variables_extraites!$A:$AD,17,FALSE) -> 42248 | AJ12: =VLOOKUP($A:$A,Variables_extraites!$A:$AD,18,FALSE) -> 43404 | AK12: =VLOOKUP($A:$A,Variables_extraites!$A:$AD,19,FALSE) -> 0 | AL12: =VLOOKUP($A:$A,Variables_extraites!$A:$AD,20,FALSE) -> 43404 | AM12: =VLOOKUP($A:$A,Variables_extraites!$A:$AD,21,FALSE) -> 37 | AN12: =VLOOKUP($A:$A,Variables_extraites!$A:$AD,22,FALSE) -> 0 | AO12: =VLOOKUP($A:$A,Variables_extraites!$A:$AD,23,FALSE) -> 43404 | AP12: =VLOOKUP($A:$A,Variables_extraites!$A:$AD,24,FALSE) -> 37 | AQ12: =VLOOKUP($A:$A,Variables_extraites!$A:$AD,25,FALSE) -> 0 | AR12: =VLOOKUP($A:$A,Variables_extraites!$A:$AD,26,FALSE) -> 43404 | AS12: =VLOOKUP($A:$A,Variables_extraites!$A:$AD,27,FALSE) -> 37 | AT12: =VLOOKUP($A:$A,Variables_extraites!$A:$AD,28,FALSE) -> 37 | AU12: =VLOOKUP($A:$A,Variables_extraites!$A:$AD,29,FALSE) -> 1156 | AV12: =VLOOKUP($A:$A,Variables_extraites!$A:$AD,30,FALSE) -> -19.19
A13: 23 | B13: 23 | C13: 2 | D13: HFpEF | E13: 10365 | F13: YES | G13: YES | H13: 72 | I13: 30.359251 | J13: 1 | K13: 4 | L13: 1 | M13: 62 | N13: 44.57 | O13: 161.94705 | P13: 5619 | Q13: 26 | R13: 39.768988 | S13: 38.224543 | T13: 20 | U13: -14.8 | V13: 62.715504 | W13: 36.06983 | X13: 37.677 | Y13: =VLOOKUP($A:$A,Variables_extraites!$A:$AD,7,FALSE) -> 0 | Z13: =VLOOKUP($A:$A,Variables_extraites!$A:$AD,8,FALSE) -> 0 | AA13: =VLOOKUP($A:$A,Variables_extraites!$A:$AD,9,FALSE) -> 9.6 | AB13: =VLOOKUP($A:$A,Variables_extraites!$A:$AD,10,FALSE) -> 1 | AC13: =VLOOKUP($A:$A,Variables_extraites!$A:$AD,11,FALSE) -> 1 | AD13: =VLOOKUP($A:$A,Variables_extraites!$A:$AD,12,FALSE) -> 0 | AE13: =VLOOKUP($A:$A,Variables_extraites!$A:$AD,13,FALSE) -> 65.405951 | AF13: =VLOOKUP($A:$A,Variables_extraites!$A:$AD,14,FALSE) -> 1.9212598 | AG13: =VLOOKUP($A:$A,Variables_extraites!$A:$AD,15,FALSE) -> 18 | AH13: =VLOOKUP($A:$A,Variables_extraites!$A:$AD,16,FALSE) -> 23 | AI13: =VLOOKUP($A:$A,Variables_extraites!$A:$AD,17,FALSE) -> 42220 | AJ13: =VLOOKUP($A:$A,Variables_extraites!$A:$AD,18,FALSE) -> 43388 | AK13: =VLOOKUP($A:$A,Variables_extraites!$A:$AD,19,FALSE) -> 0 | AL13: =VLOOKUP($A:$A,Variables_extraites!$A:$AD,20,FALSE) -> 43388 | AM13: =VLOOKUP($A:$A,Variables_extraites!$A:$AD,21,FALSE) -> 38 | AN13: =VLOOKUP($A:$A,Variables_extraites!$A:$AD,22,FALSE) -> 1 | AO13: =VLOOKUP($A:$A,Variables_extraites!$A:$AD,23,FALSE) -> 43388 | AP13: =VLOOKUP($A:$A,Variables_extraites!$A:$AD,24,FALSE) -> 38 | AQ13: =VLOOKUP($A:$A,Variables_extraites!$A:$AD,25,FALSE) -> 1 | AR13: =VLOOKUP($A:$A,Variables_extraites!$A:$AD,26,FALSE) -> 43388 | AS13: =VLOOKUP($A:$A,Variables_extraites!$A:$AD,27,FALSE) -> 38 | AT13: =VLOOKUP($A:$A,Variables_extraites!$A:$AD,28,FALSE) -> 38 | AU13: =VLOOKUP($A:$A,Variables_extraites!$A:$AD,29,FALSE) -> 1168 | AV13: =VLOOKUP($A:$A,Variables_extraites!$A:$AD,30,FALSE) -> -18.22 | AW13: 9.0088768 | AX13: 8.1583067 | AY13: 5.6624904 | AZ13: 0.81885056 | BA13: 6.9214839 | BB13: 8.3583435 | BC13: 8.7861716 | BD13: 8.4541348 | BE13: 5.9183862 | BF13: 1.5310695 | BG13: 6.0248072 | BH13: 6.4247542 | BI13: 7.5484366 | BJ13: 4.3596617 | BK13: 6.0751047 | BL13: 8.3239104 | BM13: 6.7236951 | BN13: 7.7092906 | BO13: 5.8532472 | BP13: 5.999098 | BQ13: 7.4865535 | BR13: -0.058893689 | BS13: 10.215582 | BT13: -1.3959287 | BU13: 4.3469569 | BV13: 6.0371626 | BW13: 3.0755326 | BX13: 11.183859 | BY13: 3.5459684 | BZ13: 5.1235007 | CA13: 4.7591558 | CB13: 6.060358 | CC13: 4.4058506 | CD13: 11.61151
A14: 24 | B14: 24 | C14: 2 | D14: HFpEF | E14: 10549 | F14: YES | G14: YES | H14: 78 | I14: 24.023809 | J14: 0 | K14: 3 | L14: 0 | M14: 40 | N14: 82.91 | O14: 2777.9081 | P14: 822.9 | Q14: 28 | R14: 83.573438 | S14: 12.77193 | T14: 25 | U14: -17.3 | V14: 61.936093 | W14: 38.395107 | X14: 69.7887 | Y14: =VLOOKUP($A:$A,Variables_extraites!$A:$AD,7,FALSE) -> 0 | Z14: =VLOOKUP($A:$A,Variables_extraites!$A:$AD,8,FALSE) -> 0 | AA14: =VLOOKUP($A:$A,Variables_extraites!$A:$AD,9,FALSE) -> 8.6 | AB14: =VLOOKUP($A:$A,Variables_extraites!$A:$AD,10,FALSE) -> 1 | AC14: =VLOOKUP($A:$A,Variables_extraites!$A:$AD,11,FALSE) -> 1 | AD14: =VLOOKUP($A:$A,Variables_extraites!$A:$AD,12,FALSE) -> 1 | AE14: =VLOOKUP($A:$A,Variables_extraites!$A:$AD,13,FALSE) -> 63.584906 | AF14: =VLOOKUP($A:$A,Variables_extraites!$A:$AD,14,FALSE) -> NA | AG14: =VLOOKUP($A:$A,Variables_extraites!$A:$AD,15,FALSE) -> 14.333333 | AH14: =VLOOKUP($A:$A,Variables_extraites!$A:$AD,16,FALSE) -> 24 | AI14: =VLOOKUP($A:$A,Variables_extraites!$A:$AD,17,FALSE) -> 42304 | AJ14: =VLOOKUP($A:$A,Variables_extraites!$A:$AD,18,FALSE) -> 42899 | AK14: =VLOOKUP($A:$A,Variables_extraites!$A:$AD,19,FALSE) -> 1 | AL14: =VLOOKUP($A:$A,Variables_extraites!$A:$AD,20,FALSE) -> 42899 | AM14: =VLOOKUP($A:$A,Variables_extraites!$A:$AD,21,FALSE) -> 19 | AN14: =VLOOKUP($A:$A,Variables_extraites!$A:$AD,22,FALSE) -> 1 | AO14: =VLOOKUP($A:$A,Variables_extraites!$A:$AD,23,FALSE) -> 42328 | AP14: =VLOOKUP($A:$A,Variables_extraites!$A:$AD,24,FALSE) -> 1 | AQ14: =VLOOKUP($A:$A,Variables_extraites!$A:$AD,25,FALSE) -> 1 | AR14: =VLOOKUP($A:$A,Variables_extraites!$A:$AD,26,FALSE) -> 42328 | AS14: =VLOOKUP($A:$A,Variables_extraites!$A:$AD,27,FALSE) -> 1 | AT14: =VLOOKUP($A:$A,Variables_extraites!$A:$AD,28,FALSE) -> 19 | AU14: =VLOOKUP($A:$A,Variables_extraites!$A:$AD,29,FALSE) -> 595 | AV14: =VLOOKUP($A:$A,Variables_extraites!$A:$AD,30,FALSE) -> NA | AW14: 8.5761064 | AX14: 7.6420517 | AY14: 5.4518705 | AZ14: 1.6229304 | BA14: 8.3679389 | BB14: 5.4873577 | BC14: 9.1054633 | BD14: 7.614489 | BE14: 6.1801081 | BF14: 0.82374936 | BG14: 6.6881804 | BH14: 7.1798096 | BI14: 8.3001237 | BJ14: 5.2835514 | BK14: 6.4666271 | BL14: 7.0737131 | BM14: 6.1921942 | BN14: 7.3304688 | BO14: 6.4770297 | BP14: 6.8197959 | BQ14: 8.3734307 | BR14: 1.9597702 | BS14: 9.0239206 | BT14: 1.0214797 | BU14: 4.4208866 | BV14: 6.100347 | BW14: 5.4001963 | BX14: 11.04565 | BY14: 3.3729521 | BZ14: 8.6141945 | CA14: 4.2555007 | CB14: 2.431456 | CC14: 2.4611164 | CD14: 8.0024409
A15: 26 | B15: 26 | C15: 2 | D15: HFpEF | E15: 10333 | F15: YES | G15: YES | H15: 53 | I15: 37.5 | J15: 1 | K15: 2 | L15: 1 | M15: 63 | N15: 28.8 | O15: 1228.6101 | P15: 67.1 | Q15: 18 | R15: 29.105879 | S15: 14.145833 | T15: 26 | U15: -18.2 | X15: 38.0923 | Y15: =VLOOKUP($A:$A,Variables_extraites!$A:$AD,7,FALSE) -> 0 | Z15: =VLOOKUP($A:$A,Variables_extraites!$A:$AD,8,FALSE) -> 1 | AA15: =VLOOKUP($A:$A,Variables_extraites!$A:$AD,9,FALSE) -> 10.4 | AB15: =VLOOKUP($A:$A,Variables_extraites!$A:$AD,10,FALSE) -> 1 | AC15: =VLOOKUP($A:$A,Variables_extraites!$A:$AD,11,FALSE) -> 0 | AD15: =VLOOKUP($A:$A,Variables_extraites!$A:$AD,12,FALSE) -> 0 | AE15: =VLOOKUP($A:$A,Variables_extraites!$A:$AD,13,FALSE) -> 74.603175 | AF15: =VLOOKUP($A:$A,Variables_extraites!$A:$AD,14,FALSE) -> 0.69569672 | AG15: =VLOOKUP($A:$A,Variables_extraites!$A:$AD,15,FALSE) -> 21 | AH15: =VLOOKUP($A:$A,Variables_extraites!$A:$AD,16,FALSE) -> 26 | AI15: =VLOOKUP($A:$A,Variables_extraites!$A:$AD,17,FALSE) -> 42048 | AJ15: =VLOOKUP($A:$A,Variables_extraites!$A:$AD,18,FALSE) -> 43480 | AK15: =VLOOKUP($A:$A,Variables_extraites!$A:$AD,19,FALSE) -> 0 | AL15: =VLOOKUP($A:$A,Variables_extraites!$A:$AD,20,FALSE) -> 43480 | AM15: =VLOOKUP($A:$A,Variables_extraites!$A:$AD,21,FALSE) -> 47 | AN15: =VLOOKUP($A:$A,Variables_extraites!$A:$AD,22,FALSE) -> 0 | AO15: =VLOOKUP($A:$A,Variables_extraites!$A:$AD,23,FALSE) -> 43480 | AP15: =VLOOKUP($A:$A,Variables_extraites!$A:$AD,24,FALSE) -> 47 | AQ15: =VLOOKUP($A:$A,Variables_extraites!$A:$AD,25,FALSE) -> 0 | AR15: =VLOOKUP($A:$A,Variables_extraites!$A:$AD,26,FALSE) -> 43480 | AS15: =VLOOKUP($A:$A,Variables_extraites!$A:$AD,27,FALSE) -> 47 | AT15: =VLOOKUP($A:$A,Variables_extraites!$A:$AD,28,FALSE) -> 47 | AU15: =VLOOKUP($A:$A,Variables_extraites!$A:$AD,29,FALSE) -> 1432 | AV15: =VLOOKUP($A:$A,Variables_extraites!$A:$AD,30,FALSE) -> -22.86 | AW15: 8.7173337 | AX15: 7.0381508 | AY15: 4.3750394 | AZ15: 3.2570106 | BA15: 7.9576245 | BB15: 7.5655972 | BC15: 8.3700771 | BD15: 7.3178648 | BE15: 6.0870385 | BF15: 1.169925 | BG15: 6.2639734 | BH15: 6.8027102 | BI15: 7.4139664 | BJ15: 4.1043367 | BK15: 5.746044 | BL15: 8.2771944 | BM15: 6.0889472 | BN15: 6.6431347 | BO15: 5.5533605 | BP15: 5.5062084 | BQ15: 8.1267561 | BR15: -0.64385619 | BS15: 11.679625 | BT15: 3.0107798 | BU15: 6.139142 | BV15: 7.2075025 | BW15: 5.3323499 | BX15: 11.449391 | BY15: 3.1026581 | BZ15: 8.3058793 | CA15: 4.0321008 | CB15: 3.1435118 | CC15: 6.7829982 | CD15: 8.6688454
A16: 29 | B16: 29 | C16: 2 | D16: HFpEF | E16: 10514 | F16: YES | H16: 79 | I16: 23.875433 | J16: 0 | K16: 2 | L16: 1 | M16: 34 | N16: 38.08 | O16: 123.33415 | R16: 42.169935 | T16: 13 | X16: 52.7911 | Y16: =VLOOKUP($A:$A,Variables_extraites!$A:$AD,7,FALSE) -> 0 | Z16: =VLOOKUP($A:$A,Variables_extraites!$A:$AD,8,FALSE) -> 0 | AA16: =VLOOKUP($A:$A,Variables_extraites!$A:$AD,9,FALSE) -> 9.5 | AB16: =VLOOKUP($A:$A,Variables_extraites!$A:$AD,10,FALSE) -> 0 | AC16: =VLOOKUP($A:$A,Variables_extraites!$A:$AD,11,FALSE) -> 1 | AD16: =VLOOKUP($A:$A,Variables_extraites!$A:$AD,12,FALSE) -> 1 | AE16: =VLOOKUP($A:$A,Variables_extraites!$A:$AD,13,FALSE) -> 53.478359 | AF16: =VLOOKUP($A:$A,Variables_extraites!$A:$AD,14,FALSE) -> NA | AG16: =VLOOKUP($A:$A,Variables_extraites!$A:$AD,15,FALSE) -> 16 | AH16: =VLOOKUP($A:$A,Variables_extraites!$A:$AD,16,FALSE) -> NA | AI16: =VLOOKUP($A:$A,Variables_extraites!$A:$AD,17,FALSE) -> NA | AJ16: =VLOOKUP($A:$A,Variables_extraites!$A:$AD,18,FALSE) -> 43542 | AK16: =VLOOKUP($A:$A,Variables_extraites!$A:$AD,19,FALSE) -> 0 | AL16: =VLOOKUP($A:$A,Variables_extraites!$A:$AD,20,FALSE) -> 43542 | AM16: =VLOOKUP($A:$A,Variables_extraites!$A:$AD,21,FALSE) -> 41 | AN16: =VLOOKUP($A:$A,Variables_extraites!$A:$AD,22,FALSE) -> 0 | AO16: =VLOOKUP($A:$A,Variables_extraites!$A:$AD,23,FALSE) -> 43542 | AP16: =VLOOKUP($A:$A,Variables_extraites!$A:$AD,24,FALSE) -> 41 | AQ16: =VLOOKUP($A:$A,Variables_extraites!$A:$AD,25,FALSE) -> 0 | AR16: =VLOOKUP($A:$A,Variables_extraites!$A:$AD,26,FALSE) -> 43542 | AS16: =VLOOKUP($A:$A,Variables_extraites!$A:$AD,27,FALSE) -> 41 | AT16: =VLOOKUP($A:$A,Variables_extraites!$A:$AD,28,FALSE) -> 41 | AU16: =VLOOKUP($A:$A,Variables_extraites!$A:$AD,29,FALSE) -> 1260 | AV16: =VLOOKUP($A:$A,Variables_extraites!$A:$AD,30,FALSE) -> NA
A17: 30 | B17: 30 | C17: 2 | D17: HFpEF | E17: 10334 | F17: YES | G17: YES | H17: 56 | I17: 36.71875 | J17: 1 | K17: 2 | L17: 0 | M17: 34 | N17: 25.53 | O17: 683.63377 | P17: 476.8 | Q17: 11 | R17: 23.509265 | S17: 28.863636 | T17: 47 | V17: 47.884527 | W17: 39.171243 | X17: 84.1588 | Y17: =VLOOKUP($A:$A,Variables_extraites!$A:$AD,7,FALSE) -> 0 | Z17: =VLOOKUP($A:$A,Variables_extraites!$A:$AD,8,FALSE) -> 0 | AA17: =VLOOKUP($A:$A,Variables_extraites!$A:$AD,9,FALSE) -> 10.8 | AB17: =VLOOKUP($A:$A,Variables_extraites!$A:$AD,10,FALSE) -> 1 | AC17: =VLOOKUP($A:$A,Variables_extraites!$A:$AD,11,FALSE) -> 0 | AD17: =VLOOKUP($A:$A,Variables_extraites!$A:$AD,12,FALSE) -> 0 | AE17: =VLOOKUP($A:$A,Variables_extraites!$A:$AD,13,FALSE) -> 59.505703 | AF17: =VLOOKUP($A:$A,Variables_extraites!$A:$AD,14,FALSE) -> 0.71468768 | AG17: =VLOOKUP($A:$A,Variables_extraites!$A:$AD,15,FALSE) -> 25 | AH17: =VLOOKUP($A:$A,Variables_extraites!$A:$AD,16,FALSE) -> NA | AI17: =VLOOKUP($A:$A,Variables_extraites!$A:$AD,17,FALSE) -> NA | AJ17: =VLOOKUP($A:$A,Variables_extraites!$A:$AD,18,FALSE) -> NA | AK17: =VLOOKUP($A:$A,Variables_extraites!$A:$AD,19,FALSE) -> NA | AL17: =VLOOKUP($A:$A,Variables_extraites!$A:$AD,20,FALSE) -> NA | AM17: =VLOOKUP($A:$A,Variables_extraites!$A:$AD,21,FALSE) -> NA | AN17: =VLOOKUP($A:$A,Variables_extraites!$A:$AD,22,FALSE) -> NA | AO17: =VLOOKUP($A:$A,Variables_extraites!$A:$AD,23,FALSE) -> NA | AP17: =VLOOKUP($A:$A,Variables_extraites!$A:$AD,24,FALSE) -> NA | AQ17: =VLOOKUP($A:$A,Variables_extraites!$A:$AD,25,FALSE) -> NA | AR17: =VLOOKUP($A:$A,Variables_extraites!$A:$AD,26,FALSE) -> NA | AS17: =VLOOKUP($A:$A,Variables_extraites!$A:$AD,27,FALSE) -> NA | AT17: =VLOOKUP($A:$A,Variables_extraites!$A:$AD,28,FALSE) -> NA | AU17: =VLOOKUP($A:$A,Variables_extraites!$A:$AD,29,FALSE) -> NA | AV17: =VLOOKUP($A:$A,Variables_extraites!$A:$AD,30,FALSE) -> NA | AW17: 8.4897677 | AX17: 7.6444332 | AY17: 4.2964574 | AZ17: 2.9278965 | BA17: 7.7096353 | BB17: 8.0324866 | BC17: 8.0319906 | BD17: 7.5975312 | BE17: 5.3483741 | BF17: 2.4931349 | BG17: 6.1795111 | BH17: 6.6540631 | BI17: 7.1843795 | BJ17: 3.9107327 | BK17: 6.3366404 | BL17: 8.7000929 | BM17: 5.6313954 | BN17: 6.7305041 | BO17: 3.7937919 | BP17: 6.283181 | BQ17: 8.0490317 | BR17: 1.2509616 | BS17: 9.0071955 | BT17: 0.042644337 | BU17: 5.3004898 | BV17: 6.9653225 | BW17: 5.1235007 | BX17: 10.74145 | BY17: 2.8135247 | BZ17: 7.0057368 | CA17: 4.304511 | CB17: 3.7357133 | CC17: 4.0495283 | CD17: 8.9645512
A18: 31 | B18: 31 | C18: 2 | D18: HFpEF | E18: 10299 | F18: YES | G18: YES | H18: 73 | I18: 25.065746 | J18: 1 | K18: 2 | L18: 1 | M18: 27 | N18: 35.65 | O18: 215.16023 | P18: 2891 | Q18: 18 | R18: 48.354285 | S18: 33.4375 | T18: 57 | U18: -15.2 | V18: 71.421888 | W18: 34.162488 | X18: 116.7772 | Y18: =VLOOKUP($A:$A,Variables_extraites!$A:$AD,7,FALSE) -> 0 | Z18: =VLOOKUP($A:$A,Variables_extraites!$A:$AD,8,FALSE) -> 0 | AA18: =VLOOKUP($A:$A,Variables_extraites!$A:$AD,9,FALSE) -> 9.8 | AB18: =VLOOKUP($A:$A,Variables_extraites!$A:$AD,10,FALSE) -> 1 | AC18: =VLOOKUP($A:$A,Variables_extraites!$A:$AD,11,FALSE) -> 1 | AD18: =VLOOKUP($A:$A,Variables_extraites!$A:$AD,12,FALSE) -> 0 | AE18: =VLOOKUP($A:$A,Variables_extraites!$A:$AD,13,FALSE) -> 60.105557 | AF18: =VLOOKUP($A:$A,Variables_extraites!$A:$AD,14,FALSE) -> 1.7774086 | AG18: =VLOOKUP($A:$A,Variables_extraites!$A:$AD,15,FALSE) -> 22 | AH18: =VLOOKUP($A:$A,Variables_extraites!$A:$AD,16,FALSE) -> 31 | AI18: =VLOOKUP($A:$A,Variables_extraites!$A:$AD,17,FALSE) -> 42290 | AJ18: =VLOOKUP($A:$A,Variables_extraites!$A:$AD,18,FALSE) -> 42861 | AK18: =VLOOKUP($A:$A,Variables_extraites!$A:$AD,19,FALSE) -> 1 | AL18: =VLOOKUP($A:$A,Variables_extraites!$A:$AD,20,FALSE) -> 42861 | AM18: =VLOOKUP($A:$A,Variables_extraites!$A:$AD,21,FALSE) -> 18 | AN18: =VLOOKUP($A:$A,Variables_extraites!$A:$AD,22,FALSE) -> 0 | AO18: =VLOOKUP($A:$A,Variables_extraites!$A:$AD,23,FALSE) -> 42861 | AP18: =VLOOKUP($A:$A,Variables_extraites!$A:$AD,24,FALSE) -> 18 | AQ18: =VLOOKUP($A:$A,Variables_extraites!$A:$AD,25,FALSE) -> 1 | AR18: =VLOOKUP($A:$A,Variables_extraites!$A:$AD,26,FALSE) -> 42861 | AS18: =VLOOKUP($A:$A,Variables_extraites!$A:$AD,27,FALSE) -> 18 | AT18: =VLOOKUP($A:$A,Variables_extraites!$A:$AD,28,FALSE) -> 18 | AU18: =VLOOKUP($A:$A,Variables_extraites!$A:$AD,29,FALSE) -> 571 | AV18: =VLOOKUP($A:$A,Variables_extraites!$A:$AD,30,FALSE) -> -23.1 | AW18: 9.2086977 | AX18: 7.5719043 | AY18: 5.5310695 | AZ18: 2.3103401 | BA18: 8.0618842 | BB18: 8.4037364 | BC18: 7.9926551 | BD18: 7.6237352 | BE18: 6.5112783 | BF18: 1.4854268 | BG18: 6.3974607 | BH18: 6.7889467 | BI18: 7.645082 | BJ18: 5.0552824 | BK18: 6.2605903 | BL18: 8.1704259 | BM18: 6.3275077 | BN18: 7.035074 | BO18: 6.3615929 | BP18: 6.4841381 | BQ18: 7.940754 | BR18: 1.2078929 | BS18: 9.6534721 | BT18: 1.5655972 | BU18: 3.7484612 | BV18: 6.9524501 | BW18: 5.9450926 | BX18: 10.797645 | BY18: 3.598127 | BZ18: 8.3984017 | CA18: 4.2839218 | CB18: 2.3992436 | CC18: 2.5405684 | CD18: 8.0878749
A19: 34 | B19: 34 | C19: 2 | D19: HFpEF | E19: 10335 | F19: YES | H19: 84 | I19: 16.896235 | J19: 1 | K19: 2 | L19: 0 | M19: 47 | N19: 36.34 | O19: 335.77704 | P19: 3330 | Q19: 52 | R19: 39.283369 | S19: 11.383562 | T19: 17 | U19: -14.186667 | V19: 55.36258 | W19: 28.868096 | X19: 98.4318 | Y19: =VLOOKUP($A:$A,Variables_extraites!$A:$AD,7,FALSE) -> 0 | Z19: =VLOOKUP($A:$A,Variables_extraites!$A:$AD,8,FALSE) -> 0 | AA19: =VLOOKUP($A:$A,Variables_extraites!$A:$AD,9,FALSE) -> 12.4 | AB19: =VLOOKUP($A:$A,Variables_extraites!$A:$AD,10,FALSE) -> 1 | AC19: =VLOOKUP($A:$A,Variables_extraites!$A:$AD,11,FALSE) -> 0 | AD19: =VLOOKUP($A:$A,Variables_extraites!$A:$AD,12,FALSE) -> 1 | AE19: =VLOOKUP($A:$A,Variables_extraites!$A:$AD,13,FALSE) -> 68.52861 | AF19: =VLOOKUP($A:$A,Variables_extraites!$A:$AD,14,FALSE) -> NA | AG19: =VLOOKUP($A:$A,Variables_extraites!$A:$AD,15,FALSE) -> 11 | AH19: =VLOOKUP($A:$A,Variables_extraites!$A:$AD,16,FALSE) -> 34 | AI19: =VLOOKUP($A:$A,Variables_extraites!$A:$AD,17,FALSE) -> 42199 | AJ19: =VLOOKUP($A:$A,Variables_extraites!$A:$AD,18,FALSE) -> 43437 | AK19: =VLOOKUP($A:$A,Variables_extraites!$A:$AD,19,FALSE) -> 0 | AL19: =VLOOKUP($A:$A,Variables_extraites!$A:$AD,20,FALSE) -> 43437 | AM19: =VLOOKUP($A:$A,Variables_extraites!$A:$AD,21,FALSE) -> 40 | AN19: =VLOOKUP($A:$A,Variables_extraites!$A:$AD,22,FALSE) -> 1 | AO19: =VLOOKUP($A:$A,Variables_extraites!$A:$AD,23,FALSE) -> 43000 | AP19: =VLOOKUP($A:$A,Variables_extraites!$A:$AD,24,FALSE) -> 26 | AQ19: =VLOOKUP($A:$A,Variables_extraites!$A:$AD,25,FALSE) -> 1 | AR19: =VLOOKUP($A:$A,Variables_extraites!$A:$AD,26,FALSE) -> 43000 | AS19: =VLOOKUP($A:$A,Variables_extraites!$A:$AD,27,FALSE) -> 26 | AT19: =VLOOKUP($A:$A,Variables_extraites!$A:$AD,28,FALSE) -> 40 | AU19: =VLOOKUP($A:$A,Variables_extraites!$A:$AD,29,FALSE) -> 1238 | AV19: =VLOOKUP($A:$A,Variables_extraites!$A:$AD,30,FALSE) -> NA
A20: 37 | B20: 37 | C20: 2 | D20: HFpEF | E20: 10431 | F20: YES | H20: 71 | I20: 23.138507 | J20: 1 | K20: 2 | L20: 1 | M20: 64 | N20: 45.96 | O20: 712.66131 | P20: 2495 | Q20: 29 | R20: 49.48035 | S20: 17.05314 | T20: 24 | U20: -15.666667 | V20: 78.630192 | W20: 31.678041 | X20: 34.0253 | Y20: =VLOOKUP($A:$A,Variables_extraites!$A:$AD,7,FALSE) -> 0 | Z20: =VLOOKUP($A:$A,Variables_extraites!$A:$AD,8,FALSE) -> 0 | AA20: =VLOOKUP($A:$A,Variables_extraites!$A:$AD,9,FALSE) -> 11.8 | AB20: =VLOOKUP($A:$A,Variables_extraites!$A:$AD,10,FALSE) -> 1 | AC20: =VLOOKUP($A:$A,Variables_extraites!$A:$AD,11,FALSE) -> 0 | AD20: =VLOOKUP($A:$A,Variables_extraites!$A:$AD,12,FALSE) -> 1 | AE20: =VLOOKUP($A:$A,Variables_extraites!$A:$AD,13,FALSE) -> 71.907344 | AF20: =VLOOKUP($A:$A,Variables_extraites!$A:$AD,14,FALSE) -> NA | AG20: =VLOOKUP($A:$A,Variables_extraites!$A:$AD,15,FALSE) -> 14.666667 | AH20: =VLOOKUP($A:$A,Variables_extraites!$A:$AD,16,FALSE) -> 37 | AI20: =VLOOKUP($A:$A,Variables_extraites!$A:$AD,17,FALSE) -> 42111 | AJ20: =VLOOKUP($A:$A,Variables_extraites!$A:$AD,18,FALSE) -> 43245 | AK20: =VLOOKUP($A:$A,Variables_extraites!$A:$AD,19,FALSE) -> 1 | AL20: =VLOOKUP($A:$A,Variables_extraites!$A:$AD,20,FALSE) -> 43245 | AM20: =VLOOKUP($A:$A,Variables_extraites!$A:$AD,21,FALSE) -> 37 | AN20: =VLOOKUP($A:$A,Variables_extraites!$A:$AD,22,FALSE) -> 1 | AO20: =VLOOKUP($A:$A,Variables_extraites!$A:$AD,23,FALSE) -> 42637 | AP20: =VLOOKUP($A:$A,Variables_extraites!$A:$AD,24,FALSE) -> 17 | AQ20: =VLOOKUP($A:$A,Variables_extraites!$A:$AD,25,FALSE) -> 1 | AR20: =VLOOKUP($A:$A,Variables_extraites!$A:$AD,26,FALSE) -> 42637 | AS20: =VLOOKUP($A:$A,Variables_extraites!$A:$AD,27,FALSE) -> 17 | AT20: =VLOOKUP($A:$A,Variables_extraites!$A:$AD,28,FALSE) -> 37 | AU20: =VLOOKUP($A:$A,Variables_extraites!$A:$AD,29,FALSE) -> 1133 | AV20: =VLOOKUP($A:$A,Variables_extraites!$A:$AD,30,FALSE) -> -23.116667
A21: 38 | B21: 38 | C21: 2 | D21: HFpEF | E21: 10645 | F21: YES | G21: YES | H21: 68 | I21: 23.62949 | J21: 0 | K21: 0 | L21: 0 | M21: 89 | N21: 37.63 | O21: 690.235 | P21: 1791 | Q21: 10 | R21: 46.463173 | S21: 9.56621 | T21: 23 | U21: -14.56 | V21: 55.949224 | W21: 32.837057 | X21: 16.8044 | Y21: =VLOOKUP($A:$A,Variables_extraites!$A:$AD,7,FALSE) -> 0 | Z21: =VLOOKUP($A:$A,Variables_extraites!$A:$AD,8,FALSE) -> 0 | AA21: =VLOOKUP($A:$A,Variables_extraites!$A:$AD,9,FALSE) -> 12.2 | AB21: =VLOOKUP($A:$A,Variables_extraites!$A:$AD,10,FALSE) -> 1 | AC21: =VLOOKUP($A:$A,Variables_extraites!$A:$AD,11,FALSE) -> 0 | AD21: =VLOOKUP($A:$A,Variables_extraites!$A:$AD,12,FALSE) -> 1 | AE21: =VLOOKUP($A:$A,Variables_extraites!$A:$AD,13,FALSE) -> 63.525132 | AF21: =VLOOKUP($A:$A,Variables_extraites!$A:$AD,14,FALSE) -> NA | AG21: =VLOOKUP($A:$A,Variables_extraites!$A:$AD,15,FALSE) -> 28 | AH21: =VLOOKUP($A:$A,Variables_extraites!$A:$AD,16,FALSE) -> 38 | AI21: =VLOOKUP($A:$A,Variables_extraites!$A:$AD,17,FALSE) -> 42128 | AJ21: =VLOOKUP($A:$A,Variables_extraites!$A:$AD,18,FALSE) -> 43542 | AK21: =VLOOKUP($A:$A,Variables_extraites!$A:$AD,19,FALSE) -> 0 | AL21: =VLOOKUP($A:$A,Variables_extraites!$A:$AD,20,FALSE) -> 43542 | AM21: =VLOOKUP($A:$A,Variables_extraites!$A:$AD,21,FALSE) -> 46 | AN21: =VLOOKUP($A:$A,Variables_extraites!$A:$AD,22,FALSE) -> 0 | AO21: =VLOOKUP($A:$A,Variables_extraites!$A:$AD,23,FALSE) -> 43542 | AP21: =VLOOKUP($A:$A,Variables_extraites!$A:$AD,24,FALSE) -> 46 | AQ21: =VLOOKUP($A:$A,Variables_extraites!$A:$AD,25,FALSE) -> 0 | AR21: =VLOOKUP($A:$A,Variables_extraites!$A:$AD,26,FALSE) -> 43542 | AS21: =VLOOKUP($A:$A,Variables_extraites!$A:$AD,27,FALSE) -> 46 | AT21: =VLOOKUP($A:$A,Variables_extraites!$A:$AD,28,FALSE) -> 46 | AU21: =VLOOKUP($A:$A,Variables_extraites!$A:$AD,29,FALSE) -> 1414 | AV21: =VLOOKUP($A:$A,Variables_extraites!$A:$AD,30,FALSE) -> -20.41 | AW21: 8.6310679 | AX21: 8.3717766 | AY21: 5.7189096 | AZ21: 2.3504972 | BA21: 8.4911316 | BB21: 6.742141 | BC21: 9.1847018 | BD21: 8.0050631 | BE21: 6.1739269 | BF21: 1.1309309 | BG21: 6.968206 | BH21: 7.3975463 | BI21: 8.1214817 | BJ21: 5.5762198 | BK21: 6.5362084 | BL21: 8.1629955 | BM21: 6.8812975 | BN21: 7.6711518 | BO21: 6.035184 | BP21: 6.6230767 | BQ21: 8.4220227 | BR21: 3.2509616 | BS21: 11.161963 | BT21: 3.5861642 | BU21: 5.7570232 | BV21: 6.1801081 | BW21: 5.1902198 | BX21: 10.471513 | BY21: 3.1375035 | BZ21: 8.6696292 | CA21: 3.6016965 | CB21: 1.8018835 | CC21: 2.5060617 | CD21: 7.575799
A22: 40 | B22: 40 | C22: 2 | D22: HFpEF | E22: 10509 | F22: YES | G22: YES | H22: 73 | I22: 33.834027 | J22: 0 | K22: 2 | L22: 1 | M22: 64 | N22: 110.63 | O22: 104.76655 | P22: 158.4 | Q22: 24 | R22: 19.582431 | S22: 14.022727 | T22: 31 | U22: -13.7 | V22: 63.771803 | W22: 36.015702 | X22: 54.2997 | Y22: =VLOOKUP($A:$A,Variables_extraites!$A:$AD,7,FALSE) -> 0 | Z22: =VLOOKUP($A:$A,Variables_extraites!$A:$AD,8,FALSE) -> 1 | AA22: =VLOOKUP($A:$A,Variables_extraites!$A:$AD,9,FALSE) -> 14.8 | AB22: =VLOOKUP($A:$A,Variables_extraites!$A:$AD,10,FALSE) -> 0 | AC22: =VLOOKUP($A:$A,Variables_extraites!$A:$AD,11,FALSE) -> 0 | AD22: =VLOOKUP($A:$A,Variables_extraites!$A:$AD,12,FALSE) -> 0 | AE22: =VLOOKUP($A:$A,Variables_extraites!$A:$AD,13,FALSE) -> 58.626329 | AF22: =VLOOKUP($A:$A,Variables_extraites!$A:$AD,14,FALSE) -> 0.77610063 | AG22: =VLOOKUP($A:$A,Variables_extraites!$A:$AD,15,FALSE) -> 11 | AH22: =VLOOKUP($A:$A,Variables_extraites!$A:$AD,16,FALSE) -> 40 | AI22: =VLOOKUP($A:$A,Variables_extraites!$A:$AD,17,FALSE) -> 42262 | AJ22: =VLOOKUP($A:$A,Variables_extraites!$A:$AD,18,FALSE) -> 43244 | AK22: =VLOOKUP($A:$A,Variables_extraites!$A:$AD,19,FALSE) -> 0 | AL22: =VLOOKUP($A:$A,Variables_extraites!$A:$AD,20,FALSE) -> 43244 | AM22: =VLOOKUP($A:$A,Variables_extraites!$A:$AD,21,FALSE) -> 32 | AN22: =VLOOKUP($A:$A,Variables_extraites!$A:$AD,22,FALSE) -> 0 | AO22: =VLOOKUP($A:$A,Variables_extraites!$A:$AD,23,FALSE) -> 43244 | AP22: =VLOOKUP($A:$A,Variables_extraites!$A:$AD,24,FALSE) -> 32 | AQ22: =VLOOKUP($A:$A,Variables_extraites!$A:$AD,25,FALSE) -> 0 | AR22: =VLOOKUP($A:$A,Variables_extraites!$A:$AD,26,FALSE) -> 43244 | AS22: =VLOOKUP($A:$A,Variables_extraites!$A:$AD,27,FALSE) -> 32 | AT22: =VLOOKUP($A:$A,Variables_extraites!$A:$AD,28,FALSE) -> 32 | AU22: =VLOOKUP($A:$A,Variables_extraites!$A:$AD,29,FALSE) -> 982 | AV22: =VLOOKUP($A:$A,Variables_extraites!$A:$AD,30,FALSE) -> -16.25 | AW22: 8.2176669 | AX22: 7.1627941 | AY22: 4.4409522 | AZ22: 2.7004397 | BA22: 6.7638099 | BB22: 6.7405229 | BC22: 8.5247768 | BD22: 7.8712276 | BE22: 5.9049657 | BF22: 2.2839218 | BG22: 6.8593484 | BH22: 7.0678108 | BI22: 7.3431413 | BJ22: 4.052242 | BK22: 6.0746767 | BL22: 7.4323749 | BM22: 5.6102867 | BN22: 6.2494453 | BO22: 4.6853796 | BP22: 5.6602099 | BQ22: 8.1369399 | BR22: 2.6937657 | BS22: 10.751117 | BT22: 1.5058909 | BU22: 5.4124428 | BV22: 7.0083166 | BW22: 4.5360529 | BX22: 10.71041 | BY22: 3.3419857 | BZ22: 7.3388701 | CA22: 4.1101962 | CB22: 3.3715404 | CC22: 2.7186771 | CD22: 9.2452263
A23: 41 | B23: 41 | C23: 2 | D23: HFpEF | E23: 10432 | F23: YES | H23: 78 | I23: 37.729725 | J23: 1 | K23: 2 | L23: 1 | M23: 61 | N23: 46.86 | O23: 435.73259 | P23: 2441 | Q23: 14 | R23: 44.798505 | S23: 14.102041 | T23: 35.366667 | U23: -18.553333 | V23: 49.950967 | W23: 30.164534 | X23: 77.5146 | Y23: =VLOOKUP($A:$A,Variables_extraites!$A:$AD,7,FALSE) -> 0 | Z23: =VLOOKUP($A:$A,Variables_extraites!$A:$AD,8,FALSE) -> 0 | AA23: =VLOOKUP($A:$A,Variables_extraites!$A:$AD,9,FALSE) -> 10.7 | AB23: =VLOOKUP($A:$A,Variables_extraites!$A:$AD,10,FALSE) -> 1 | AC23: =VLOOKUP($A:$A,Variables_extraites!$A:$AD,11,FALSE) -> 0 | AD23: =VLOOKUP($A:$A,Variables_extraites!$A:$AD,12,FALSE) -> 1 | AE23: =VLOOKUP($A:$A,Variables_extraites!$A:$AD,13,FALSE) -> 61.273337 | AF23: =VLOOKUP($A:$A,Variables_extraites!$A:$AD,14,FALSE) -> NA | AG23: =VLOOKUP($A:$A,Variables_extraites!$A:$AD,15,FALSE) -> 14.333333 | AH23: =VLOOKUP($A:$A,Variables_extraites!$A:$AD,16,FALSE) -> 41 | AI23: =VLOOKUP($A:$A,Variables_extraites!$A:$AD,17,FALSE) -> 42202 | AJ23: =VLOOKUP($A:$A,Variables_extraites!$A:$AD,18,FALSE) -> 43326 | AK23: =VLOOKUP($A:$A,Variables_extraites!$A:$AD,19,FALSE) -> 0 | AL23: =VLOOKUP($A:$A,Variables_extraites!$A:$AD,20,FALSE) -> 43326 | AM23: =VLOOKUP($A:$A,Variables_extraites!$A:$AD,21,FALSE) -> 36 | AN23: =VLOOKUP($A:$A,Variables_extraites!$A:$AD,22,FALSE) -> 1 | AO23: =VLOOKUP($A:$A,Variables_extraites!$A:$AD,23,FALSE) -> 42668 | AP23: =VLOOKUP($A:$A,Variables_extraites!$A:$AD,24,FALSE) -> 15 | AQ23: =VLOOKUP($A:$A,Variables_extraites!$A:$AD,25,FALSE) -> 1 | AR23: =VLOOKUP($A:$A,Variables_extraites!$A:$AD,26,FALSE) -> 42668 | AS23: =VLOOKUP($A:$A,Variables_extraites!$A:$AD,27,FALSE) -> 15 | AT23: =VLOOKUP($A:$A,Variables_extraites!$A:$AD,28,FALSE) -> 36 | AU23: =VLOOKUP($A:$A,Variables_extraites!$A:$AD,29,FALSE) -> 1124 | AV23: =VLOOKUP($A:$A,Variables_extraites!$A:$AD,30,FALSE) -> NA
A24: 43 | B24: 43 | C24: 2 | D24: HFpEF | E24: 10394 | F24: YES | G24: YES | H24: 72 | I24: 15.22192 | J24: 1 | K24: 3 | L24: 0 | M24: 40 | N24: 56.82 | O24: 353.54088 | P24: 2219 | Q24: 16 | R24: 46.572799 | S24: 9.5530726 | T24: 40 | U24: -14.14 | X24: 68.3847 | Y24: =VLOOKUP($A:$A,Variables_extraites!$A:$AD,7,FALSE) -> 1 | Z24: =VLOOKUP($A:$A,Variables_extraites!$A:$AD,8,FALSE) -> 0 | AA24: =VLOOKUP($A:$A,Variables_extraites!$A:$AD,9,FALSE) -> 15.3 | AB24: =VLOOKUP($A:$A,Variables_extraites!$A:$AD,10,FALSE) -> 0 | AC24: =VLOOKUP($A:$A,Variables_extraites!$A:$AD,11,FALSE) -> 0 | AD24: =VLOOKUP($A:$A,Variables_extraites!$A:$AD,12,FALSE) -> 1 | AE24: =VLOOKUP($A:$A,Variables_extraites!$A:$AD,13,FALSE) -> 65.261383 | AF24: =VLOOKUP($A:$A,Variables_extraites!$A:$AD,14,FALSE) -> NA | AG24: =VLOOKUP($A:$A,Variables_extraites!$A:$AD,15,FALSE) -> 14.333333 | AH24: =VLOOKUP($A:$A,Variables_extraites!$A:$AD,16,FALSE) -> 43 | AI24: =VLOOKUP($A:$A,Variables_extraites!$A:$AD,17,FALSE) -> 42242 | AJ24: =VLOOKUP($A:$A,Variables_extraites!$A:$AD,18,FALSE) -> 42695 | AK24: =VLOOKUP($A:$A,Variables_extraites!$A:$AD,19,FALSE) -> 1 | AL24: =VLOOKUP($A:$A,Variables_extraites!$A:$AD,20,FALSE) -> 42695 | AM24: =VLOOKUP($A:$A,Variables_extraites!$A:$AD,21,FALSE) -> 14 | AN24: =VLOOKUP($A:$A,Variables_extraites!$A:$AD,22,FALSE) -> 1 | AO24: =VLOOKUP($A:$A,Variables_extraites!$A:$AD,23,FALSE) -> 42382 | AP24: =VLOOKUP($A:$A,Variables_extraites!$A:$AD,24,FALSE) -> 4 | AQ24: =VLOOKUP($A:$A,Variables_extraites!$A:$AD,25,FALSE) -> 1 | AR24: =VLOOKUP($A:$A,Variables_extraites!$A:$AD,26,FALSE) -> 42382 | AS24: =VLOOKUP($A:$A,Variables_extraites!$A:$AD,27,FALSE) -> 4 | AT24: =VLOOKUP($A:$A,Variables_extraites!$A:$AD,28,FALSE) -> 14 | AU24: =VLOOKUP($A:$A,Variables_extraites!$A:$AD,29,FALSE) -> 453 | AV24: =VLOOKUP($A:$A,Variables_extraites!$A:$AD,30,FALSE) -> NA | AW24: 8.5597212 | AX24: 7.842916 | AY24: 5.3483741 | AZ24: 3.619413 | BA24: 7.6322682 | BB24: 7.7974021 | BC24: 8.6815547 | BD24: 7.9935612 | BE24: 6.2813273 | BF24: 0.94860085 | BG24: 6.3705131 | BH24: 6.9318012 | BI24: 7.9509349 | BJ24: 4.7473874 | BK24: 6.2785424 | BL24: 8.157448 | BM24: 6.7090149 | BN24: 7.0110036 | BO24: 6.0263574 | BP24: 6.1582562 | BQ24: 8.0001127 | BR24: -0.074000581 | BS24: 10.186919 | BT24: -0.97143085 | BU24: 4.2735159 | BV24: 6.5169607 | BW24: 3.5071603 | BX24: 10.802258 | BY24: 3.6724253 | BZ24: 4.9713136 | CA24: 5.0263574 | CB24: 5.8309442 | CC24: 4.3475165 | CD24: 11.15835
A25: 51 | B25: 51 | C25: 2 | D25: HFpEF | E25: 10336 | F25: YES | G25: YES | H25: 83 | I25: 27.555556 | J25: 1 | K25: 2 | L25: 0 | M25: 60 | N25: 53.3 | O25: 254.27693 | P25: 2091 | Q25: 49 | R25: 53.260756 | S25: 27.15625 | T25: 28 | U25: -14.9 | V25: 55.0203 | W25: 34.315961 | X25: 67.8122 | Y25: =VLOOKUP($A:$A,Variables_extraites!$A:$AD,7,FALSE) -> 0 | Z25: =VLOOKUP($A:$A,Variables_extraites!$A:$AD,8,FALSE) -> 0 | AA25: =VLOOKUP($A:$A,Variables_extraites!$A:$AD,9,FALSE) -> 13.4 | AB25: =VLOOKUP($A:$A,Variables_extraites!$A:$AD,10,FALSE) -> 1 | AC25: =VLOOKUP($A:$A,Variables_extraites!$A:$AD,11,FALSE) -> 0 | AD25: =VLOOKUP($A:$A,Variables_extraites!$A:$AD,12,FALSE) -> 1 | AE25: =VLOOKUP($A:$A,Variables_extraites!$A:$AD,13,FALSE) -> 68.408262 | AF25: =VLOOKUP($A:$A,Variables_extraites!$A:$AD,14,FALSE) -> 3.381323 | AG25: =VLOOKUP($A:$A,Variables_extraites!$A:$AD,15,FALSE) -> 15 | AH25: =VLOOKUP($A:$A,Variables_extraites!$A:$AD,16,FALSE) -> 51 | AI25: =VLOOKUP($A:$A,Variables_extraites!$A:$AD,17,FALSE) -> 42083 | AJ25: =VLOOKUP($A:$A,Variables_extraites!$A:$AD,18,FALSE) -> 43123 | AK25: =VLOOKUP($A:$A,Variables_extraites!$A:$AD,19,FALSE) -> 1 | AL25: =VLOOKUP($A:$A,Variables_extraites!$A:$AD,20,FALSE) -> 43123 | AM25: =VLOOKUP($A:$A,Variables_extraites!$A:$AD,21,FALSE) -> 34 | AN25: =VLOOKUP($A:$A,Variables_extraites!$A:$AD,22,FALSE) -> 1 | AO25: =VLOOKUP($A:$A,Variables_extraites!$A:$AD,23,FALSE) -> 43047 | AP25: =VLOOKUP($A:$A,Variables_extraites!$A:$AD,24,FALSE) -> 31 | AQ25: =VLOOKUP($A:$A,Variables_extraites!$A:$AD,25,FALSE) -> 1 | AR25: =VLOOKUP($A:$A,Variables_extraites!$A:$AD,26,FALSE) -> 43047 | AS25: =VLOOKUP($A:$A,Variables_extraites!$A:$AD,27,FALSE) -> 31 | AT25: =VLOOKUP($A:$A,Variables_extraites!$A:$AD,28,FALSE) -> 34 | AU25: =VLOOKUP($A:$A,Variables_extraites!$A:$AD,29,FALSE) -> 1040 | AV25: =VLOOKUP($A:$A,Variables_extraites!$A:$AD,30,FALSE) -> -27.42 | AW25: 8.7109442 | AX25: 7.6065903 | AY25: 5.1830895 | AZ25: 1.7655347 | BA25: 8.0924929 | BB25: 5.2861419 | BC25: 9.300467 | BD25: 7.3904269 | BE25: 5.8419731 | BF25: 1.275007 | BG25: 6.0723202 | BH25: 6.5902128 | BI25: 7.6022906 | BJ25: 4.1826923 | BK25: 5.9742999 | BL25: 6.9642831 | BM25: 6.2494453 | BN25: 6.5332519 | BO25: 5.6037747 | BP25: 6.5337191 | BQ25: 7.7499364 | BR25: 4.4679315 | BS25: 9.8487638 | BT25: 2.0356239 | BU25: 6.3717331 | BV25: 6.9411063 | BW25: 5.8534967 | BX25: 10.903129 | BY25: 3.3812834 | BZ25: 8.5050176 | CA25: 4.2257377 | CB25: 2.3981111 | CC25: 1.9038015 | CD25: 7.8131399
A26: 53 | B26: 53 | C26: 2 | D26: HFpEF | E26: 10395 | F26: YES | G26: YES | H26: 85 | I26: 26.233556 | J26: 1 | K26: 2 | L26: 0 | M26: 40 | N26: 47.05 | O26: 89.29229 | P26: 4906 | Q26: 49 | R26: 50.423989 | S26: 30.590164 | T26: 34 | U26: -12.97 | X26: 56.7487 | Y26: =VLOOKUP($A:$A,Variables_extraites!$A:$AD,7,FALSE) -> 0 | Z26: =VLOOKUP($A:$A,Variables_extraites!$A:$AD,8,FALSE) -> 0 | AA26: =VLOOKUP($A:$A,Variables_extraites!$A:$AD,9,FALSE) -> 13 | AB26: =VLOOKUP($A:$A,Variables_extraites!$A:$AD,10,FALSE) -> 1 | AC26: =VLOOKUP($A:$A,Variables_extraites!$A:$AD,11,FALSE) -> 1 | AD26: =VLOOKUP($A:$A,Variables_extraites!$A:$AD,12,FALSE) -> 1 | AE26: =VLOOKUP($A:$A,Variables_extraites!$A:$AD,13,FALSE) -> 47.010551 | AF26: =VLOOKUP($A:$A,Variables_extraites!$A:$AD,14,FALSE) -> 1.5245098 | AG26: =VLOOKUP($A:$A,Variables_extraites!$A:$AD,15,FALSE) -> 19 | AH26: =VLOOKUP($A:$A,Variables_extraites!$A:$AD,16,FALSE) -> 53 | AI26: =VLOOKUP($A:$A,Variables_extraites!$A:$AD,17,FALSE) -> 42080 | AJ26: =VLOOKUP($A:$A,Variables_extraites!$A:$AD,18,FALSE) -> 43231 | AK26: =VLOOKUP($A:$A,Variables_extraites!$A:$AD,19,FALSE) -> 0 | AL26: =VLOOKUP($A:$A,Variables_extraites!$A:$AD,20,FALSE) -> 43231 | AM26: =VLOOKUP($A:$A,Variables_extraites!$A:$AD,21,FALSE) -> 37 | AN26: =VLOOKUP($A:$A,Variables_extraites!$A:$AD,22,FALSE) -> 1 | AO26: =VLOOKUP($A:$A,Variables_extraites!$A:$AD,23,FALSE) -> 42214 | AP26: =VLOOKUP($A:$A,Variables_extraites!$A:$AD,24,FALSE) -> 4 | AQ26: =VLOOKUP($A:$A,Variables_extraites!$A:$AD,25,FALSE) -> 1 | AR26: =VLOOKUP($A:$A,Variables_extraites!$A:$AD,26,FALSE) -> 42214 | AS26: =VLOOKUP($A:$A,Variables_extraites!$A:$AD,27,FALSE) -> 4 | AT26: =VLOOKUP($A:$A,Variables_extraites!$A:$AD,28,FALSE) -> 37 | AU26: =VLOOKUP($A:$A,Variables_extraites!$A:$AD,29,FALSE) -> 1151 | AV26: =VLOOKUP($A:$A,Variables_extraites!$A:$AD,30,FALSE) -> -25.51 | AW26: 8.7030384 | AX26: 7.6678921 | AY26: 4.7532836 | AZ26: 1.5704629 | BA26: 8.0831602 | BB26: 4.9514013 | BC26: 9.1107182 | BD26: 7.6611368 | BE26: 6.1255685 | BF26: 1.1505597 | BG26: 6.0654431 | BH26: 6.4024152 | BI26: 7.5625477 | BJ26: 4.3603643 | BK26: 5.8081276 | BL26: 7.6564964 | BM26: 5.9231492 | BN26: 6.2414589 | BO26: 5.515069 | BP26: 5.7860736 | BQ26: 7.87621 | BR26: 3.7246503 | BS26: 9.8152872 | BT26: 1.5210507 | BU26: 5.6539199 | BV26: 7.2134445 | BW26: 5.3586072 | BX26: 10.611532 | BY26: 3.3812834 | BZ26: 8.2160183 | CA26: 4.5855635 | CB26: 2.3955138 | CC26: 1.9292696 | CD26: 8.2942365
